<?xml version="1.0" encoding="UTF-8"?>
<!-- Generated by org.testng.reporters.JUnitReportReporter -->
<testsuite hostname="Moni" failures="1" tests="7" name="org.maven.Cls1" time="0.031" errors="0" timestamp="25 Oct 2021 10:13:38 GMT" skipped="3">
  <testcase classname="org.maven.Cls1" name="supe" time="0.014"/>
  <testcase classname="org.maven.Cls1" name="the" time="0.002"/>
  <testcase classname="org.maven.Cls1" name="logic" time="0.002">
    <skipped/>
  </testcase> <!-- logic -->
  <testcase classname="org.maven.Cls1" name="logic" time="0.004">
    <skipped/>
  </testcase> <!-- logic -->
  <testcase classname="org.maven.Cls1" name="logic" time="0.003">
    <failure message="WRONG CONDITION expected [true] but found [false]" type="java.lang.AssertionError">
      <![CDATA[java.lang.AssertionError: WRONG CONDITION expected [true] but found [false]
at org.testng.Assert.fail(Assert.java:96)
at org.testng.Assert.failNotEquals(Assert.java:776)
at org.testng.Assert.assertTrue(Assert.java:44)
at org.maven.Cls1.logic(Cls1.java:10)
at java.base/jdk.internal.reflect.NativeMethodAccessorImpl.invoke0(Native Method)
at java.base/jdk.internal.reflect.NativeMethodAccessorImpl.invoke(NativeMethodAccessorImpl.java:64)
at java.base/jdk.internal.reflect.DelegatingMethodAccessorImpl.invoke(DelegatingMethodAccessorImpl.java:43)
at java.base/java.lang.reflect.Method.invoke(Method.java:564)
at org.testng.internal.MethodInvocationHelper.invokeMethod(MethodInvocationHelper.java:124)
at org.testng.internal.Invoker.invokeMethod(Invoker.java:583)
at org.testng.internal.Invoker.retryFailed(Invoker.java:839)
at org.testng.internal.Invoker.invokeTestMethods(Invoker.java:1010)
at org.testng.internal.TestMethodWorker.invokeTestMethods(TestMethodWorker.java:125)
at org.testng.internal.TestMethodWorker.run(TestMethodWorker.java:109)
at org.testng.TestRunner.privateRun(TestRunner.java:648)
at org.testng.TestRunner.run(TestRunner.java:505)
at org.testng.SuiteRunner.runTest(SuiteRunner.java:455)
at org.testng.SuiteRunner.runSequentially(SuiteRunner.java:450)
at org.testng.SuiteRunner.privateRun(SuiteRunner.java:415)
at org.testng.SuiteRunner.run(SuiteRunner.java:364)
at org.testng.SuiteRunnerWorker.runSuite(SuiteRunnerWorker.java:52)
at org.testng.SuiteRunnerWorker.run(SuiteRunnerWorker.java:84)
at org.testng.TestNG.runSuitesSequentially(TestNG.java:1208)
at org.testng.TestNG.runSuitesLocally(TestNG.java:1137)
at org.testng.TestNG.runSuites(TestNG.java:1049)
at org.testng.TestNG.run(TestNG.java:1017)
at org.testng.remote.AbstractRemoteTestNG.run(AbstractRemoteTestNG.java:115)
at org.testng.remote.RemoteTestNG.initAndRun(RemoteTestNG.java:251)
at org.testng.remote.RemoteTestNG.main(RemoteTestNG.java:77)
]]>
    </failure>
  </testcase> <!-- logic -->
  <testcase classname="org.maven.Cls1" name="logic" time="0.003">
    <skipped/>
  </testcase> <!-- logic -->
  <testcase classname="org.maven.Cls1" name="man" time="0.003"/>
</testsuite> <!-- org.maven.Cls1 -->
